<?xml version='1.0' encoding='UTF-8'?>
<robot name="mirror_agent_hand">
  <link name="link_0_0">
    <inertial>
      <origin xyz="0.0 0.0 0.0" rpy="0.0 -0.0 0.0"/>
      <mass value="0.1"/>
      <inertia ixx="0.01" ixy="0.0" ixz="0.0" iyy="0.01" iyz="0.0" izz="0.01"/>
    </inertial>
    <visual>
      <geometry>
        <mesh filename="/home/qyx/Desktop/Isaaclab_other/agent_for_isaaclab_mirror/mesh/link_0_0_capsule.stl"/>
      </geometry>
      <origin xyz="0.0 0.0 0.0175" rpy="0.0 -0.0 0.0"/>
    </visual>
    <collision name="collision_link_0_0">
      <geometry>
        <mesh filename="/home/qyx/Desktop/Isaaclab_other/agent_for_isaaclab_mirror/mesh/link_0_0_capsule.stl"/>
      </geometry>
      <origin xyz="0.0 0.0 0.0" rpy="0.0 -0.0 0.0"/>
    </collision>
  </link>
  <link name="link_1_0">
    <inertial>
      <origin xyz="0.0 0.0 0.0" rpy="0.0 -0.0 0.0"/>
      <mass value="0.1"/>
      <inertia ixx="0.01" ixy="0.0" ixz="0.0" iyy="0.01" iyz="0.0" izz="0.01"/>
    </inertial>
    <visual>
      <geometry>
        <mesh filename="/home/qyx/Desktop/Isaaclab_other/agent_for_isaaclab_mirror/mesh/link_1_0_capsule.stl"/>
      </geometry>
      <origin xyz="0.0 0.0 0.02087830009779897" rpy="0.0 -0.0 0.0"/>
    </visual>
    <collision name="collision_link_1_0">
      <geometry>
        <mesh filename="/home/qyx/Desktop/Isaaclab_other/agent_for_isaaclab_mirror/mesh/link_1_0_capsule.stl"/>
      </geometry>
      <origin xyz="0.0 0.0 0.0" rpy="0.0 -0.0 0.0"/>
    </collision>
  </link>
  <link name="link_1_1">
    <inertial>
      <origin xyz="0.0 0.0 0.0" rpy="0.0 -0.0 0.0"/>
      <mass value="0.1"/>
      <inertia ixx="0.01" ixy="0.0" ixz="0.0" iyy="0.01" iyz="0.0" izz="0.01"/>
    </inertial>
    <visual>
      <geometry>
        <mesh filename="/home/qyx/Desktop/Isaaclab_other/agent_for_isaaclab_mirror/mesh/link_1_1_capsule.stl"/>
      </geometry>
      <origin xyz="0.0 0.0 0.012460927547521027" rpy="0.0 -0.0 0.0"/>
    </visual>
    <collision name="collision_link_1_1">
      <geometry>
        <mesh filename="/home/qyx/Desktop/Isaaclab_other/agent_for_isaaclab_mirror/mesh/link_1_1_capsule.stl"/>
      </geometry>
      <origin xyz="0.0 0.0 0.0" rpy="0.0 -0.0 0.0"/>
    </collision>
  </link>
  <link name="link_1_2">
    <inertial>
      <origin xyz="0.0 0.0 0.0" rpy="0.0 -0.0 0.0"/>
      <mass value="0.1"/>
      <inertia ixx="0.01" ixy="0.0" ixz="0.0" iyy="0.01" iyz="0.0" izz="0.01"/>
    </inertial>
    <visual>
      <geometry>
        <mesh filename="/home/qyx/Desktop/Isaaclab_other/agent_for_isaaclab_mirror/mesh/link_1_2_capsule.stl"/>
      </geometry>
      <origin xyz="0.0 0.0 0.008224160417422594" rpy="0.0 -0.0 0.0"/>
    </visual>
    <collision name="collision_link_1_2">
      <geometry>
        <mesh filename="/home/qyx/Desktop/Isaaclab_other/agent_for_isaaclab_mirror/mesh/link_1_2_capsule.stl"/>
      </geometry>
      <origin xyz="0.0 0.0 0.0" rpy="0.0 -0.0 0.0"/>
    </collision>
  </link>
  <link name="link_2_0">
    <inertial>
      <origin xyz="0.0 0.0 0.0" rpy="0.0 -0.0 0.0"/>
      <mass value="0.1"/>
      <inertia ixx="0.01" ixy="0.0" ixz="0.0" iyy="0.01" iyz="0.0" izz="0.01"/>
    </inertial>
    <visual>
      <geometry>
        <mesh filename="/home/qyx/Desktop/Isaaclab_other/agent_for_isaaclab_mirror/mesh/link_2_0_capsule.stl"/>
      </geometry>
      <origin xyz="0.0 0.0 0.02622419725878079" rpy="0.0 -0.0 0.0"/>
    </visual>
    <collision name="collision_link_2_0">
      <geometry>
        <mesh filename="/home/qyx/Desktop/Isaaclab_other/agent_for_isaaclab_mirror/mesh/link_2_0_capsule.stl"/>
      </geometry>
      <origin xyz="0.0 0.0 0.0" rpy="0.0 -0.0 0.0"/>
    </collision>
  </link>
  <link name="link_2_1">
    <inertial>
      <origin xyz="0.0 0.0 0.0" rpy="0.0 -0.0 0.0"/>
      <mass value="0.1"/>
      <inertia ixx="0.01" ixy="0.0" ixz="0.0" iyy="0.01" iyz="0.0" izz="0.01"/>
    </inertial>
    <visual>
      <geometry>
        <mesh filename="/home/qyx/Desktop/Isaaclab_other/agent_for_isaaclab_mirror/mesh/link_2_1_capsule.stl"/>
      </geometry>
      <origin xyz="0.0 0.0 0.012056296105140505" rpy="0.0 -0.0 0.0"/>
    </visual>
    <collision name="collision_link_2_1">
      <geometry>
        <mesh filename="/home/qyx/Desktop/Isaaclab_other/agent_for_isaaclab_mirror/mesh/link_2_1_capsule.stl"/>
      </geometry>
      <origin xyz="0.0 0.0 0.0" rpy="0.0 -0.0 0.0"/>
    </collision>
  </link>
  <link name="link_2_2">
    <inertial>
      <origin xyz="0.0 0.0 0.0" rpy="0.0 -0.0 0.0"/>
      <mass value="0.1"/>
      <inertia ixx="0.01" ixy="0.0" ixz="0.0" iyy="0.01" iyz="0.0" izz="0.01"/>
    </inertial>
    <visual>
      <geometry>
        <mesh filename="/home/qyx/Desktop/Isaaclab_other/agent_for_isaaclab_mirror/mesh/link_2_2_capsule.stl"/>
      </geometry>
      <origin xyz="0.0 0.0 0.0089732511695911" rpy="0.0 -0.0 0.0"/>
    </visual>
    <collision name="collision_link_2_2">
      <geometry>
        <mesh filename="/home/qyx/Desktop/Isaaclab_other/agent_for_isaaclab_mirror/mesh/link_2_2_capsule.stl"/>
      </geometry>
      <origin xyz="0.0 0.0 0.0" rpy="0.0 -0.0 0.0"/>
    </collision>
  </link>
  <link name="link_2_3">
    <inertial>
      <origin xyz="0.0 0.0 0.0" rpy="0.0 -0.0 0.0"/>
      <mass value="0.1"/>
      <inertia ixx="0.01" ixy="0.0" ixz="0.0" iyy="0.01" iyz="0.0" izz="0.01"/>
    </inertial>
    <visual>
      <geometry>
        <mesh filename="/home/qyx/Desktop/Isaaclab_other/agent_for_isaaclab_mirror/mesh/link_2_3_capsule.stl"/>
      </geometry>
      <origin xyz="0.0 0.0 0.010723389272153402" rpy="0.0 -0.0 0.0"/>
    </visual>
    <collision name="collision_link_2_3">
      <geometry>
        <mesh filename="/home/qyx/Desktop/Isaaclab_other/agent_for_isaaclab_mirror/mesh/link_2_3_capsule.stl"/>
      </geometry>
      <origin xyz="0.0 0.0 0.0" rpy="0.0 -0.0 0.0"/>
    </collision>
  </link>
  <link name="link_3_0">
    <inertial>
      <origin xyz="0.0 0.0 0.0" rpy="0.0 -0.0 0.0"/>
      <mass value="0.1"/>
      <inertia ixx="0.01" ixy="0.0" ixz="0.0" iyy="0.01" iyz="0.0" izz="0.01"/>
    </inertial>
    <visual>
      <geometry>
        <mesh filename="/home/qyx/Desktop/Isaaclab_other/agent_for_isaaclab_mirror/mesh/link_3_0_capsule.stl"/>
      </geometry>
      <origin xyz="0.0 0.0 0.030907364895025408" rpy="0.0 -0.0 0.0"/>
    </visual>
    <collision name="collision_link_3_0">
      <geometry>
        <mesh filename="/home/qyx/Desktop/Isaaclab_other/agent_for_isaaclab_mirror/mesh/link_3_0_capsule.stl"/>
      </geometry>
      <origin xyz="0.0 0.0 0.0" rpy="0.0 -0.0 0.0"/>
    </collision>
  </link>
  <link name="link_3_1">
    <inertial>
      <origin xyz="0.0 0.0 0.0" rpy="0.0 -0.0 0.0"/>
      <mass value="0.1"/>
      <inertia ixx="0.01" ixy="0.0" ixz="0.0" iyy="0.01" iyz="0.0" izz="0.01"/>
    </inertial>
    <visual>
      <geometry>
        <mesh filename="/home/qyx/Desktop/Isaaclab_other/agent_for_isaaclab_mirror/mesh/link_3_1_capsule.stl"/>
      </geometry>
      <origin xyz="0.0 0.0 0.01987566311774224" rpy="0.0 -0.0 0.0"/>
    </visual>
    <collision name="collision_link_3_1">
      <geometry>
        <mesh filename="/home/qyx/Desktop/Isaaclab_other/agent_for_isaaclab_mirror/mesh/link_3_1_capsule.stl"/>
      </geometry>
      <origin xyz="0.0 0.0 0.0" rpy="0.0 -0.0 0.0"/>
    </collision>
  </link>
  <link name="link_3_2">
    <inertial>
      <origin xyz="0.0 0.0 0.0" rpy="0.0 -0.0 0.0"/>
      <mass value="0.1"/>
      <inertia ixx="0.01" ixy="0.0" ixz="0.0" iyy="0.01" iyz="0.0" izz="0.01"/>
    </inertial>
    <visual>
      <geometry>
        <mesh filename="/home/qyx/Desktop/Isaaclab_other/agent_for_isaaclab_mirror/mesh/link_3_2_capsule.stl"/>
      </geometry>
      <origin xyz="0.0 0.0 0.011312765312345947" rpy="0.0 -0.0 0.0"/>
    </visual>
    <collision name="collision_link_3_2">
      <geometry>
        <mesh filename="/home/qyx/Desktop/Isaaclab_other/agent_for_isaaclab_mirror/mesh/link_3_2_capsule.stl"/>
      </geometry>
      <origin xyz="0.0 0.0 0.0" rpy="0.0 -0.0 0.0"/>
    </collision>
  </link>
  <link name="link_3_3">
    <inertial>
      <origin xyz="0.0 0.0 0.0" rpy="0.0 -0.0 0.0"/>
      <mass value="0.1"/>
      <inertia ixx="0.01" ixy="0.0" ixz="0.0" iyy="0.01" iyz="0.0" izz="0.01"/>
    </inertial>
    <visual>
      <geometry>
        <mesh filename="/home/qyx/Desktop/Isaaclab_other/agent_for_isaaclab_mirror/mesh/link_3_3_capsule.stl"/>
      </geometry>
      <origin xyz="0.0 0.0 0.006761868971446342" rpy="0.0 -0.0 0.0"/>
    </visual>
    <collision name="collision_link_3_3">
      <geometry>
        <mesh filename="/home/qyx/Desktop/Isaaclab_other/agent_for_isaaclab_mirror/mesh/link_3_3_capsule.stl"/>
      </geometry>
      <origin xyz="0.0 0.0 0.0" rpy="0.0 -0.0 0.0"/>
    </collision>
  </link>
  <link name="link_4_0">
    <inertial>
      <origin xyz="0.0 0.0 0.0" rpy="0.0 -0.0 0.0"/>
      <mass value="0.1"/>
      <inertia ixx="0.01" ixy="0.0" ixz="0.0" iyy="0.01" iyz="0.0" izz="0.01"/>
    </inertial>
    <visual>
      <geometry>
        <mesh filename="/home/qyx/Desktop/Isaaclab_other/agent_for_isaaclab_mirror/mesh/link_4_0_capsule.stl"/>
      </geometry>
      <origin xyz="0.0 0.0 0.02500985799566052" rpy="0.0 -0.0 0.0"/>
    </visual>
    <collision name="collision_link_4_0">
      <geometry>
        <mesh filename="/home/qyx/Desktop/Isaaclab_other/agent_for_isaaclab_mirror/mesh/link_4_0_capsule.stl"/>
      </geometry>
      <origin xyz="0.0 0.0 0.0" rpy="0.0 -0.0 0.0"/>
    </collision>
  </link>
  <link name="link_4_1">
    <inertial>
      <origin xyz="0.0 0.0 0.0" rpy="0.0 -0.0 0.0"/>
      <mass value="0.1"/>
      <inertia ixx="0.01" ixy="0.0" ixz="0.0" iyy="0.01" iyz="0.0" izz="0.01"/>
    </inertial>
    <visual>
      <geometry>
        <mesh filename="/home/qyx/Desktop/Isaaclab_other/agent_for_isaaclab_mirror/mesh/link_4_1_capsule.stl"/>
      </geometry>
      <origin xyz="0.0 0.0 0.0111885918639237" rpy="0.0 -0.0 0.0"/>
    </visual>
    <collision name="collision_link_4_1">
      <geometry>
        <mesh filename="/home/qyx/Desktop/Isaaclab_other/agent_for_isaaclab_mirror/mesh/link_4_1_capsule.stl"/>
      </geometry>
      <origin xyz="0.0 0.0 0.0" rpy="0.0 -0.0 0.0"/>
    </collision>
  </link>
  <link name="link_4_2">
    <inertial>
      <origin xyz="0.0 0.0 0.0" rpy="0.0 -0.0 0.0"/>
      <mass value="0.1"/>
      <inertia ixx="0.01" ixy="0.0" ixz="0.0" iyy="0.01" iyz="0.0" izz="0.01"/>
    </inertial>
    <visual>
      <geometry>
        <mesh filename="/home/qyx/Desktop/Isaaclab_other/agent_for_isaaclab_mirror/mesh/link_4_2_capsule.stl"/>
      </geometry>
      <origin xyz="0.0 0.0 0.00979619720435719" rpy="0.0 -0.0 0.0"/>
    </visual>
    <collision name="collision_link_4_2">
      <geometry>
        <mesh filename="/home/qyx/Desktop/Isaaclab_other/agent_for_isaaclab_mirror/mesh/link_4_2_capsule.stl"/>
      </geometry>
      <origin xyz="0.0 0.0 0.0" rpy="0.0 -0.0 0.0"/>
    </collision>
  </link>
  <link name="link_4_3">
    <inertial>
      <origin xyz="0.0 0.0 0.0" rpy="0.0 -0.0 0.0"/>
      <mass value="0.1"/>
      <inertia ixx="0.01" ixy="0.0" ixz="0.0" iyy="0.01" iyz="0.0" izz="0.01"/>
    </inertial>
    <visual>
      <geometry>
        <mesh filename="/home/qyx/Desktop/Isaaclab_other/agent_for_isaaclab_mirror/mesh/link_4_3_capsule.stl"/>
      </geometry>
      <origin xyz="0.0 0.0 0.009104868932837849" rpy="0.0 -0.0 0.0"/>
    </visual>
    <collision name="collision_link_4_3">
      <geometry>
        <mesh filename="/home/qyx/Desktop/Isaaclab_other/agent_for_isaaclab_mirror/mesh/link_4_3_capsule.stl"/>
      </geometry>
      <origin xyz="0.0 0.0 0.0" rpy="0.0 -0.0 0.0"/>
    </collision>
  </link>
  <link name="link_5_0">
    <inertial>
      <origin xyz="0.0 0.0 0.0" rpy="0.0 -0.0 0.0"/>
      <mass value="0.1"/>
      <inertia ixx="0.01" ixy="0.0" ixz="0.0" iyy="0.01" iyz="0.0" izz="0.01"/>
    </inertial>
    <visual>
      <geometry>
        <mesh filename="/home/qyx/Desktop/Isaaclab_other/agent_for_isaaclab_mirror/mesh/link_5_0_capsule.stl"/>
      </geometry>
      <origin xyz="0.0 0.0 0.025580679216170323" rpy="0.0 -0.0 0.0"/>
    </visual>
    <collision name="collision_link_5_0">
      <geometry>
        <mesh filename="/home/qyx/Desktop/Isaaclab_other/agent_for_isaaclab_mirror/mesh/link_5_0_capsule.stl"/>
      </geometry>
      <origin xyz="0.0 0.0 0.0" rpy="0.0 -0.0 0.0"/>
    </collision>
  </link>
  <link name="link_5_1">
    <inertial>
      <origin xyz="0.0 0.0 0.0" rpy="0.0 -0.0 0.0"/>
      <mass value="0.1"/>
      <inertia ixx="0.01" ixy="0.0" ixz="0.0" iyy="0.01" iyz="0.0" izz="0.01"/>
    </inertial>
    <visual>
      <geometry>
        <mesh filename="/home/qyx/Desktop/Isaaclab_other/agent_for_isaaclab_mirror/mesh/link_5_1_capsule.stl"/>
      </geometry>
      <origin xyz="0.0 0.0 0.006960702474303201" rpy="0.0 -0.0 0.0"/>
    </visual>
    <collision name="collision_link_5_1">
      <geometry>
        <mesh filename="/home/qyx/Desktop/Isaaclab_other/agent_for_isaaclab_mirror/mesh/link_5_1_capsule.stl"/>
      </geometry>
      <origin xyz="0.0 0.0 0.0" rpy="0.0 -0.0 0.0"/>
    </collision>
  </link>
  <link name="link_5_2">
    <inertial>
      <origin xyz="0.0 0.0 0.0" rpy="0.0 -0.0 0.0"/>
      <mass value="0.1"/>
      <inertia ixx="0.01" ixy="0.0" ixz="0.0" iyy="0.01" iyz="0.0" izz="0.01"/>
    </inertial>
    <visual>
      <geometry>
        <mesh filename="/home/qyx/Desktop/Isaaclab_other/agent_for_isaaclab_mirror/mesh/link_5_2_capsule.stl"/>
      </geometry>
      <origin xyz="0.0 0.0 0.004781537491756905" rpy="0.0 -0.0 0.0"/>
    </visual>
    <collision name="collision_link_5_2">
      <geometry>
        <mesh filename="/home/qyx/Desktop/Isaaclab_other/agent_for_isaaclab_mirror/mesh/link_5_2_capsule.stl"/>
      </geometry>
      <origin xyz="0.0 0.0 0.0" rpy="0.0 -0.0 0.0"/>
    </collision>
  </link>
  <link name="link_5_3">
    <inertial>
      <origin xyz="0.0 0.0 0.0" rpy="0.0 -0.0 0.0"/>
      <mass value="0.1"/>
      <inertia ixx="0.01" ixy="0.0" ixz="0.0" iyy="0.01" iyz="0.0" izz="0.01"/>
    </inertial>
    <visual>
      <geometry>
        <mesh filename="/home/qyx/Desktop/Isaaclab_other/agent_for_isaaclab_mirror/mesh/link_5_3_capsule.stl"/>
      </geometry>
      <origin xyz="0.0 0.0 0.005965367788134214" rpy="0.0 -0.0 0.0"/>
    </visual>
    <collision name="collision_link_5_3">
      <geometry>
        <mesh filename="/home/qyx/Desktop/Isaaclab_other/agent_for_isaaclab_mirror/mesh/link_5_3_capsule.stl"/>
      </geometry>
      <origin xyz="0.0 0.0 0.0" rpy="0.0 -0.0 0.0"/>
    </collision>
  </link>
  <joint name="link_0_0_to_link_1_0" type="revolute">
    <limit effort="15.0" velocity="2.0" lower="0.0" upper="1.0"/>
    <parent link="link_0_0"/>
    <child link="link_1_0"/>
    <axis xyz="1. 0. 0."/>
    <origin xyz="-0.015 0.0 0.0" rpy="3.141592653589793 -1.2715926535897932 3.141592653589793"/>
  </joint>
  <joint name="link_1_0_to_link_1_1" type="revolute">
    <limit effort="10.0" velocity="1.5" lower="0.0" upper="1.57"/>
    <parent link="link_1_0"/>
    <child link="link_1_1"/>
    <axis xyz="1. 0. 0."/>
    <origin xyz="0.0 0.0 0.045" rpy="0.0 -0.0 0.0"/>
  </joint>
  <joint name="link_1_1_to_link_1_2" type="revolute">
    <limit effort="5.0" velocity="1.5" lower="0.0" upper="1.57"/>
    <parent link="link_1_1"/>
    <child link="link_1_2"/>
    <axis xyz="1. 0. 0."/>
    <origin xyz="0.0 0.0 0.026" rpy="0.0 -0.0 0.0"/>
  </joint>
  <joint name="link_0_0_to_link_2_0" type="revolute">
    <limit effort="15.0" velocity="2.0" lower="0.0" upper="1.0"/>
    <parent link="link_0_0"/>
    <child link="link_2_0"/>
    <axis xyz="1. 0. 0."/>
    <origin xyz="-0.015 0.0 0.01" rpy="3.141592653589793 -1.4715926535897936 3.141592653589793"/>
  </joint>
  <joint name="link_2_0_to_link_2_1" type="revolute">
    <limit effort="10.0" velocity="1.5" lower="0.0" upper="1.57"/>
    <parent link="link_2_0"/>
    <child link="link_2_1"/>
    <axis xyz="1. 0. 0."/>
    <origin xyz="0.0 0.0 0.049999999999999996" rpy="0.0 -0.0 0.0"/>
  </joint>
  <joint name="link_2_1_to_link_2_2" type="revolute">
    <limit effort="5.0" velocity="1.5" lower="0.0" upper="1.57"/>
    <parent link="link_2_1"/>
    <child link="link_2_2"/>
    <axis xyz="1. 0. 0."/>
    <origin xyz="0.0 0.0 0.032" rpy="0.0 -0.0 0.0"/>
  </joint>
  <joint name="link_2_2_to_link_2_3" type="revolute">
    <limit effort="5.0" velocity="1.5" lower="0.0" upper="1.57"/>
    <parent link="link_2_2"/>
    <child link="link_2_3"/>
    <axis xyz="1. 0. 0."/>
    <origin xyz="0.0 0.0 0.024" rpy="0.0 -0.0 0.0"/>
  </joint>
  <joint name="link_0_0_to_link_3_0" type="revolute">
    <limit effort="15.0" velocity="2.0" lower="0.0" upper="1.0"/>
    <parent link="link_0_0"/>
    <child link="link_3_0"/>
    <axis xyz="1. 0. 0."/>
    <origin xyz="-0.015 0.0 0.02" rpy="0.0 -1.570000000000127 0.0"/>
  </joint>
  <joint name="link_3_0_to_link_3_1" type="revolute">
    <limit effort="10.0" velocity="1.5" lower="0.0" upper="1.57"/>
    <parent link="link_3_0"/>
    <child link="link_3_1"/>
    <axis xyz="1. 0. 0."/>
    <origin xyz="0.0 0.0 0.052000000000000005" rpy="0.0 -0.0 0.0"/>
  </joint>
  <joint name="link_3_1_to_link_3_2" type="revolute">
    <limit effort="5.0" velocity="1.5" lower="0.0" upper="1.57"/>
    <parent link="link_3_1"/>
    <child link="link_3_2"/>
    <axis xyz="1. 0. 0."/>
    <origin xyz="0.0 0.0 0.033" rpy="0.0 -0.0 0.0"/>
  </joint>
  <joint name="link_3_2_to_link_3_3" type="revolute">
    <limit effort="5.0" velocity="1.5" lower="0.0" upper="1.57"/>
    <parent link="link_3_2"/>
    <child link="link_3_3"/>
    <axis xyz="1. 0. 0."/>
    <origin xyz="0.0 0.0 0.0255" rpy="0.0 -0.0 0.0"/>
  </joint>
  <joint name="link_0_0_to_link_4_0" type="revolute">
    <limit effort="15.0" velocity="2.0" lower="0.0" upper="1.0"/>
    <parent link="link_0_0"/>
    <child link="link_4_0"/>
    <axis xyz="1. 0. 0."/>
    <origin xyz="-0.015 0.0 0.03" rpy="0.0 -1.4699999999999993 0.0"/>
  </joint>
  <joint name="link_4_0_to_link_4_1" type="revolute">
    <limit effort="10.0" velocity="1.5" lower="0.0" upper="1.57"/>
    <parent link="link_4_0"/>
    <child link="link_4_1"/>
    <axis xyz="1. 0. 0."/>
    <origin xyz="0.0 0.0 0.043000000000000003" rpy="0.0 -0.0 0.0"/>
  </joint>
  <joint name="link_4_1_to_link_4_2" type="revolute">
    <limit effort="5.0" velocity="1.5" lower="0.0" upper="1.57"/>
    <parent link="link_4_1"/>
    <child link="link_4_2"/>
    <axis xyz="1. 0. 0."/>
    <origin xyz="0.0 0.0 0.033" rpy="0.0 -0.0 0.0"/>
  </joint>
  <joint name="link_4_2_to_link_4_3" type="revolute">
    <limit effort="5.0" velocity="1.5" lower="0.0" upper="1.57"/>
    <parent link="link_4_2"/>
    <child link="link_4_3"/>
    <axis xyz="1. 0. 0."/>
    <origin xyz="0.0 0.0 0.0245" rpy="0.0 -0.0 0.0"/>
  </joint>
  <joint name="link_0_0_to_link_5_0" type="revolute">
    <limit effort="15.0" velocity="2.0" lower="0.0" upper="1.0"/>
    <parent link="link_0_0"/>
    <child link="link_5_0"/>
    <axis xyz="1. 0. 0."/>
    <origin xyz="-0.015 0.0 0.04" rpy="0.0 -1.3699999999999999 0.0"/>
  </joint>
  <joint name="link_5_0_to_link_5_1" type="revolute">
    <limit effort="10.0" velocity="1.5" lower="0.0" upper="1.57"/>
    <parent link="link_5_0"/>
    <child link="link_5_1"/>
    <axis xyz="1. 0. 0."/>
    <origin xyz="0.0 0.0 0.042" rpy="0.0 -0.0 0.0"/>
  </joint>
  <joint name="link_5_1_to_link_5_2" type="revolute">
    <limit effort="5.0" velocity="1.5" lower="0.0" upper="1.57"/>
    <parent link="link_5_1"/>
    <child link="link_5_2"/>
    <axis xyz="1. 0. 0."/>
    <origin xyz="0.0 0.0 0.023" rpy="0.0 -0.0 0.0"/>
  </joint>
  <joint name="link_5_2_to_link_5_3" type="revolute">
    <limit effort="5.0" velocity="1.5" lower="0.0" upper="1.57"/>
    <parent link="link_5_2"/>
    <child link="link_5_3"/>
    <axis xyz="1. 0. 0."/>
    <origin xyz="0.0 0.0 0.018" rpy="0.0 -0.0 0.0"/>
  </joint>
</robot>
